Workbook

Sheet en_US
A1: =Cadenas!A1 -> Lunes | B1: Monday
A2: =Cadenas!A2 -> Martes | B2: Tuesday
A3: =Cadenas!A3 -> Miércoles | B3: Wednesday
A4: =Cadenas!A4 -> Jueves | B4: Thursday
A5: =Cadenas!A5 -> Viernes | B5: Friday
A6: =Cadenas!A6 -> Sábado | B6: Saturday
A7: =Cadenas!A7 -> Domingo | B7: Sunday
A8: =Cadenas!A8 -> Servicio iniciado | B8: Service initiated
A9: =Cadenas!A9 -> Dispositivo conectado | B9: Device connected
A10: =Cadenas!A10 -> Axón conectado | B10: Axon connected
A11: =Cadenas!A11 -> Servicio caído | B11: Service down
A12: =Cadenas!A12 -> Dispositivo desconectado | B12: Device disconnected
... A412: =Cadenas!A412 -> Alarmas | B412: Alarms
A413: Esta red utiliza | B413: This network uses
A414: =Cadenas!A414 -> Fechas | B414: Dates
A415: =Cadenas!A415 -> IP | B415: IP
A416: =Cadenas!A416 -> Encender | B416: Turn on
A417: =Cadenas!A417 -> Apagar | B417: Turn off
A418: =Cadenas!A418 -> Encender (bajo consumo) | B418: Turn on (low consumption)
A419: =Cadenas!A419 -> Encender (medio consumo) | B419: Turn on (medium consumption)
A420: =Cadenas!A420 -> Encender 1 luz | B420: Turn on 1 light
A421: Enciende 2 luces | B421: Turn on 2 lights
A422: =Cadenas!A422 -> Encender 5 segundos | B422: Turn on 5 seconds
A423: =Cadenas!A423 -> usuario | B423: user
A424: =Cadenas!A424 -> Red actual establecida correctamente | B424: Current network established correctly
A425: =Cadenas!A425 -> límite máximo | B425: maximum limit
A426: =Cadenas!A426 -> Recalcular | B426: Recalculate
A427: =Cadenas!A427 -> No hay datos disponibles | B427: No data available
A428: =Cadenas!A428 -> Usuario actual modificado correctamente | B428: Current user modified correctly
A429: =Cadenas!A429 -> Alarma | B429: Alarm
A430: =Cadenas!A430 -> Internet | B430: Internet
A431: =Cadenas!A431 -> Local | B431: Local
A432: =Cadenas!A432 -> Clase | B432: Class
A433: =Cadenas!A433 -> Ninguno | B433: None
... A1013: =Cadenas!A1013 -> Número máximo de históricos de reglas superado (se muestran los más recientes) | B1013: Maximum number of rule logs reached (most recent ones are shown)
A1014: La potencia de algún tramo debe ser igual o mayor que | B1014: Power of at least one segment must be equal or greater than
A1015: =Cadenas!A1015 -> La anchura de la ventana es demasiado pequeña para poder realizar la exportación a PDF | B1015: Window's width is too small to generate the PDF file
A1016: =Cadenas!A1016 -> No se puede eliminar el actuador porque tiene acciones asignadas | B1016: The actuator could not be deleted because it has actions assigned to it
A1017: =Cadenas!A1017 -> No se puede eliminar el grupo porque tiene acciones asignadas | B1017: The group could not be deleted because it has actions assigned to it
A1018: =Cadenas!A1018 -> No se puede eliminar el grupo porque tiene sucesos de timeout de envío asignados | B1018: The group could not be deleted because it has sending timeout occurrences assigned to it
...

Sheet Cadenas
A1: Lunes
A2: Martes
A3: Miércoles
A4: Jueves
A5: Viernes
A6: Sábado
A7: Domingo
A8: Servicio iniciado
A9: Dispositivo conectado
A10: Axón conectado
A11: Servicio caído
A12: Dispositivo desconectado
... A3953: El número de días de exportación de costes de conceptos de consumo es mayor que el máximo permitido

Sheet JSON
A1: =CONCATENATE("""",Cadenas!A1,""":{") -> "Lunes":{ | B1: =CONCATENATE("""en_US"":""",en_US!B1,"""") -> "en_US":"Monday" | C1: =CONCATENATE("},") -> },
A2: =CONCATENATE("""",Cadenas!A2,""":{") -> "Martes":{ | B2: =CONCATENATE("""en_US"":""",en_US!B2,"""") -> "en_US":"Tuesday" | C2: =CONCATENATE("},") -> },
A3: =CONCATENATE("""",Cadenas!A3,""":{") -> "Miércoles":{ | B3: =CONCATENATE("""en_US"":""",en_US!B3,"""") -> "en_US":"Wednesday" | C3: =CONCATENATE("},") -> },
A4: =CONCATENATE("""",Cadenas!A4,""":{") -> "Jueves":{ | B4: =CONCATENATE("""en_US"":""",en_US!B4,"""") -> "en_US":"Thursday" | C4: =CONCATENATE("},") -> },
A5: =CONCATENATE("""",Cadenas!A5,""":{") -> "Viernes":{ | B5: =CONCATENATE("""en_US"":""",en_US!B5,"""") -> "en_US":"Friday" | C5: =CONCATENATE("},") -> },
A6: =CONCATENATE("""",Cadenas!A6,""":{") -> "Sábado":{ | B6: =CONCATENATE("""en_US"":""",en_US!B6,"""") -> "en_US":"Saturday" | C6: =CONCATENATE("},") -> },
A7: =CONCATENATE("""",Cadenas!A7,""":{") -> "Domingo":{ | B7: =CONCATENATE("""en_US"":""",en_US!B7,"""") -> "en_US":"Sunday" | C7: =CONCATENATE("},") -> },
A8: =CONCATENATE("""",Cadenas!A8,""":{") -> "Servicio iniciado":{ | B8: =CONCATENATE("""en_US"":""",en_US!B8,"""") -> "en_US":"Service initiated" | C8: =CONCATENATE("},") -> },
A9: =CONCATENATE("""",Cadenas!A9,""":{") -> "Dispositivo conectado":{ | B9: =CONCATENATE("""en_US"":""",en_US!B9,"""") -> "en_US":"Device connected" | C9: =CONCATENATE("},") -> },
A10: =CONCATENATE("""",Cadenas!A10,""":{") -> "Axón conectado":{ | B10: =CONCATENATE("""en_US"":""",en_US!B10,"""") -> "en_US":"Axon connected" | C10: =CONCATENATE("},") -> },
A11: =CONCATENATE("""",Cadenas!A11,""":{") -> "Servicio caído":{ | B11: =CONCATENATE("""en_US"":""",en_US!B11,"""") -> "en_US":"Service down" | C11: =CONCATENATE("},") -> },
A12: =CONCATENATE("""",Cadenas!A12,""":{") -> "Dispositivo desconectado":{ | B12: =CONCATENATE("""en_US"":""",en_US!B12,"""") -> "en_US":"Device disconnected" | C12: =CONCATENATE("},") -> },
... A3961: =CONCATENATE("""",Cadenas!A3961,""":{") -> "":{ | B3961: =CONCATENATE("""en_US"":""",en_US!B3961,"""") -> "en_US":"" | C3961: =CONCATENATE("},") -> },
